from odoo import models, fields, api
from odoo.exceptions import UserError

class PurchaseOrderTransport(models.Model):
    _inherit = 'purchase.order'

    transport_id = fields.Many2one(
            'transport.transport', 
            string='Transporte', 
            required=True
        )
    
    driver_id = fields.Many2one(
        'transport.driver', 
        string='Conductor', 
        required=True,
    )

    chasis = fields.Many2one(
        'transport.patent', 
        string='Chasis', 
        required=False,
    )

    acoplado = fields.Many2one(
        'transport.patent', 
        string='Acoplado', 
        required=False,
    )
    dni = fields.Char('Identificaci√≥n')

    @api.onchange('driver_id')
    def _onchange_driver_id(self):
        for order in self:
            if order.driver_id:
                order.dni = order.driver_id.dni
                
    def button_confirm(self):
        res = super(PurchaseOrderTransport, self).button_confirm()
        for picking in self.picking_ids:
            picking.acoplado = self.acoplado.id
            picking.chasis = self.chasis.id
            picking.driver_id = self.driver_id.id
            picking.transport_ids = self.transport_id.id
            #Asignar DNI si el conductor no lo tiene
            if not picking.driver_id.dni:
                picking.driver_id.dni = picking.dni
        return res